Workbook

Sheet Gantt Chart
B2: North Service Pro
B4: PROJECT TITLE | F4: North Services | K4: COMPANY NAME | R4: North Cleaning Services GmbH
B5: PROJECT MANAGER | F5: George Sebastian Cucuiet | K5: DATE | R5: =today() -> 46007
B8: WBS NUMBER | D8: TASK TITLE | E8: Monthly COST | F8: TASK OWNER | G8: START DATE | H8: DUE DATE | I8: DURATION | J8: PCT OF TASK COMPLETE | K8: PHASE ONE - tools preparation | Z8: PHASE TWO | AO8: PHASE THREE | BD8: PHASE FOUR
K9: WEEK 31 | P9: WEEK 32 | U9: WEEK 33 | Z9: WEEK 4 | AE9: WEEK 5 | AJ9: WEEK 6 | AO9: WEEK 7 | AT9: WEEK 8 | AY9: WEEK 9 | BD9: WEEK 10 | BI9: WEEK 11 | BN9: WEEK 12
K10: M | L10: T | M10: W | N10: R | O10: F | P10: M | Q10: T | R10: W | S10: R | T10: F | U10: M | V10: T | W10: W | X10: R | Y10: F | Z10: M | AA10: T | AB10: W | AC10: R | AD10: F | AE10: M | AF10: T | AG10: W | AH10: R | AI10: F | AJ10: M | AK10: T | AL10: W | AM10: R | AN10: F | AO10: M | AP10: T | AQ10: W | AR10: R | AS10: F | AT10: M | AU10: T | AV10: W | AW10: R | AX10: F | AY10: M | AZ10: T | BA10: W | BB10: R | BC10: F | BD10: M | BE10: T | BF10: W | BG10: R | BH10: F | BI10: M | BJ10: T | BK10: W | BL10: R | BM10: F | BN10: M | BO10: T | BP10: W | BQ10: R | BR10: F
B11: 1 | D11: Website
B12: 1.1 | C12: SEO | F12: George | G12: =MIN(G13:G20) -> 45871 | H12: =MAX(H13:H20) -> 45892 | I12: =DAYS360(G12,H12) -> 21 | J12: 0
B13: 1.1.1 | D13: Audit | F13: George | G13: 45871 | H13: =G13+I13 -> 45875 | I13: 4 | J13: 0
B14: 1.1.2 | D14: Update WordPress Core & Plugins | F14: George | G14: 45872 | H14: 45886 | I14: =DAYS360(G14,H14) -> 14 | J14: 0
B15: 1.1.3 | D15: Configure Yoast SEO (Free or Premium) | F15: George | G15: 45873 | H15: 45887 | I15: =DAYS360(G15,H15) -> 14 | J15: 0
B16: 1.1.4 | D16: Complete SEO Audit (Technical + On-page) | F16: George | G16: 45874 | H16: 45888 | I16: =DAYS360(G16,H16) -> 14 | J16: 0
B17: 1.1.5 | D17: Keyword Research & Competitor Analysis | F17: George | G17: 45875 | H17: 45889 | I17: =DAYS360(G17,H17) -> 14 | J17: 0
B18: 1.1.6 | D18: On-Page Optimization (Titles, Meta, Alt Text) | F18: George | G18: 45876 | H18: 45890 | I18: =DAYS360(G18,H18) -> 14 | J18: 0
B19: 1.1.7 | D19: Local SEO Setup (Google My Business, Directories) | F19: George | G19: 45877 | H19: 45891 | I19: =DAYS360(G19,H19) -> 14 | J19: 0
B20: 1.1.8 | D20: Backlink Outreach Campaign | F20: George | G20: 45878 | H20: 45892 | I20: =DAYS360(G20,H20) -> 14 | J20: 0
B21: 1.2 | C21: Email marketing | F21: George | I21: =DAYS360(G21,H21) -> 0 | J21: 0
B22: 1.2.1 | D22: ='Task Managemnt'!A10 -> Define Job Profiles & Requirements | F22: George | I22: =DAYS360(G22,H22) -> 0 | J22: 0
B23: 1.2.2 | D23: ='Task Managemnt'!A11 -> Publish Job Ads on Platforms | F23: George | I23: =DAYS360(G23,H23) -> 0 | J23: 0
B24: 1.2.3 | D24: ='Task Managemnt'!A12 -> Screen Applicants | F24: George | I24: =DAYS360(G24,H24) -> 0 | J24: 0
B25: 1.2.4 | D25: ='Task Managemnt'!A13 -> Conduct Interviews | F25: George | I25: =DAYS360(G25,H25) -> 0 | J25: 0
B26: 1.2.5 | D26: ='Task Managemnt'!A14 -> Hire & Onboard Staff | F26: George | I26: =DAYS360(G26,H26) -> 0 | J26: 0
B27: 1.3 | C27: Email marketing | F27: George | I27: =DAYS360(G27,H27) -> 0 | J27: 0
B28: 1.2.1 | F28: George | I28: =DAYS360(G28,H28) -> 0 | J28: 0
B29: 1.2.2 | F29: George | I29: =DAYS360(G29,H29) -> 0 | J29: 0
B30: 1.2.3 | F30: George | I30: =DAYS360(G30,H30) -> 0 | J30: 0
B31: 1.2.4 | F31: George | I31: =DAYS360(G31,H31) -> 0 | J31: 0
B32: 1.2.5 | F32: George | I32: =DAYS360(G32,H32) -> 0 | J32: 0
B33: 2 | D33: LLM's
B34: 2.1 | C34: Gather Website Requirements & UX Wireframe | F34: George | G34: 45876 | H34: 45877 | I34: =DAYS360(G34,H34) -> 1 | J34: 1
B35: 2.2 | C35: Set Up Django Development Environment | F35: George | I35: 3 | J35: 0
B36: 2.3 | C36: Develop Core Backend (Models, Admin)
B37: 2.4 | C37: Implement Frontend (Templates, CSS, JS) | I37: 0 | J37: 0
B38: 2.5 | C38: Integrate SEO & API Features
B39: 2.6 | C39: Testing & Bug Fixes
B40: 2.7 | C40: Launch New Django Website
B41: 2.8 | F41: George | I41: 0 | J41: 0
B42: 3 | D42: LLM's
B43: 3.1 | C43: OpenAI | E43: 29 | F43: George | G43: 45876 | H43: 45877 | I43: =DAYS360(G43,H43) -> 1 | J43: 1
B44: 3.1 | C44: Claude | E44: 20 | F44: George | I44: 3 | J44: 0
...

Sheet Task Managemnt
A3: Update WordPress Core & Plugins | B3: SEO | C3: 45881 | D3: 2 | E3: 45883
A4: Configure Yoast SEO (Free or Premium) | B4: SEO | C4: 45883 | D4: 3 | E4: 45886
A5: Complete SEO Audit (Technical + On-page) | B5: SEO | C5: 45886 | D5: 5 | E5: 45891
A6: Keyword Research & Competitor Analysis | B6: SEO | C6: 45891 | D6: 5 | E6: 45896
A7: On-Page Optimization (Titles, Meta, Alt Text) | B7: SEO | C7: 45896 | D7: 7 | E7: 45903
A8: Local SEO Setup (Google My Business, Directories) | B8: SEO | C8: 45903 | D8: 5 | E8: 45908
A9: Backlink Outreach Campaign | B9: SEO | C9: 45908 | D9: 10 | E9: 45918
A10: Define Job Profiles & Requirements | B10: Recruitment | C10: 45881 | D10: 3 | E10: 45884
A11: Publish Job Ads on Platforms | B11: Recruitment | C11: 45884 | D11: 4 | E11: 45888
A12: Screen Applicants | B12: Recruitment | C12: 45888 | D12: 7 | E12: 45895
A13: Conduct Interviews | B13: Recruitment | C13: 45895 | D13: 5 | E13: 45900
A14: Hire & Onboard Staff | B14: Recruitment | C14: 45900 | D14: 5 | E14: 45905
... A21: Launch New Django Website | B21: Website Reconstruction | C21: 45920 | D21: 2 | E21: 45922
